<?xml version='1.0' encoding='utf-8'?>
<robot name="my_urdf"><link name="base_link"><visual><origin xyz="0 0 0" rpy="0.0 0.0 0.0" /><material name="white"><color rgba="0.8 0.8 0.8 1" /></material><geometry><mesh filename="../../all_meshes/cabinet.obj" scale="1 1 1" /></geometry></visual><collision><origin xyz="0 0 0" rpy="0.0 0.0 0.0" /><geometry><mesh filename="../../all_meshes/cabinet.obj" scale="1 1 1" /></geometry></collision><inertial><mass value="1" /><inertia ixx="1e-4" ixy="0" ixz="0" iyy="1e-4" iyz="0" izz="1e-4" /></inertial></link><link name="doorL0"><visual><origin xyz="0 0 0" rpy="0 0 0" /><material name="white"><color rgba="0.8 0.8 0.8 1" /></material><geometry><mesh filename="../../all_meshes/parts/doorL.obj" scale="1 1.3233333333333333 2.6566666666666667" /></geometry></visual><collision><origin xyz="0 0 0" rpy="0 0 0" /><geometry><mesh filename="../../all_meshes/parts/doorL.obj" scale="1 1.3233333333333333 2.6566666666666667" /></geometry></collision><inertial><mass value="0.2" /><inertia ixx="1e-4" ixy="0" ixz="0" iyy="1e-4" iyz="0" izz="1e-4" /></inertial></link><joint name="doorL0_to_base_link" type="revolute"><axis xyz="0 0 1" /><limit effort="5" lower="-1.57" upper="0" velocity="2.283" /><origin xyz="0 0.0 0.0" rpy="0.0 0.0 0.0" /><parent link="base_link" /><child link="doorL0" /></joint><link name="doorR1"><visual><origin xyz="0 0 0" rpy="0 0 0" /><material name="white"><color rgba="0.8 0.8 0.8 1" /></material><geometry><mesh filename="../../all_meshes/parts/doorR.obj" scale="1 1.3233333333333333 2.6566666666666667" /></geometry></visual><collision><origin xyz="0 0 0" rpy="0 0 0" /><geometry><mesh filename="../../all_meshes/parts/doorR.obj" scale="1 1.3233333333333333 2.6566666666666667" /></geometry></collision><inertial><mass value="0.2" /><inertia ixx="1e-4" ixy="0" ixz="0" iyy="1e-4" iyz="0" izz="1e-4" /></inertial></link><joint name="doorR1_to_base_link" type="revolute"><axis xyz="0 0 1" /><limit effort="5" lower="0" upper="1.57" velocity="2.283" /><origin xyz="0 0.6666666666666666 0.0" rpy="-0.0 -0.0 -0.0" /><parent link="base_link" /><child link="doorR1" /></joint><link name="doorR2"><visual><origin xyz="0 0 0" rpy="0 0 0" /><material name="white"><color rgba="0.8 0.8 0.8 1" /></material><geometry><mesh filename="../../all_meshes/parts/doorR.obj" scale="1 1.3233333333333333 2.6566666666666667" /></geometry></visual><collision><origin xyz="0 0 0" rpy="0 0 0" /><geometry><mesh filename="../../all_meshes/parts/doorR.obj" scale="1 1.3233333333333333 2.6566666666666667" /></geometry></collision><inertial><mass value="0.2" /><inertia ixx="1e-4" ixy="0" ixz="0" iyy="1e-4" iyz="0" izz="1e-4" /></inertial></link><joint name="doorR2_to_base_link" type="revolute"><axis xyz="0 0 1" /><limit effort="5" lower="0" upper="1.57" velocity="2.283" /><origin xyz="0 1.0 0.0" rpy="-0.0 -0.0 -0.0" /><parent link="base_link" /><child link="doorR2" /></joint><link name="drawer3"><visual><origin xyz="0 0 0" rpy="0 0 0" /><material name="white"><color rgba="0.8 0.8 0.8 1" /></material><geometry><mesh filename="../../all_meshes/parts/drawer.obj" scale="1 1.3133333333333332 1.3133333333333332" /></geometry></visual><collision><origin xyz="0 0 0" rpy="0 0 0" /><geometry><mesh filename="../../all_meshes/parts/drawer.obj" scale="1 1.3133333333333332 1.3133333333333332" /></geometry></collision><inertial><mass value="0.2" /><inertia ixx="1e-4" ixy="0" ixz="0" iyy="1e-4" iyz="0" izz="1e-4" /></inertial></link><joint name="drawer3_to_base_link" type="prismatic"><axis xyz="1 0 0" /><limit effort="5" lower="0" upper="0.4" velocity="2.283" /><origin xyz="0 0.0 0.6666666666666666" rpy="0.0 0.0 0.0" /><parent link="base_link" /><child link="drawer3" /></joint><link name="drawer4"><visual><origin xyz="0 0 0" rpy="0 0 0" /><material name="white"><color rgba="0.8 0.8 0.8 1" /></material><geometry><mesh filename="../../all_meshes/parts/drawer.obj" scale="1 1.3133333333333332 1.3133333333333332" /></geometry></visual><collision><origin xyz="0 0 0" rpy="0 0 0" /><geometry><mesh filename="../../all_meshes/parts/drawer.obj" scale="1 1.3133333333333332 1.3133333333333332" /></geometry></collision><inertial><mass value="0.2" /><inertia ixx="1e-4" ixy="0" ixz="0" iyy="1e-4" iyz="0" izz="1e-4" /></inertial></link><joint name="drawer4_to_base_link" type="prismatic"><axis xyz="1 0 0" /><limit effort="5" lower="0" upper="0.4" velocity="2.283" /><origin xyz="0 0.3333333333333333 0.6666666666666666" rpy="0.0 0.0 0.0" /><parent link="base_link" /><child link="drawer4" /></joint><link name="drawer5"><visual><origin xyz="0 0 0" rpy="0 0 0" /><material name="white"><color rgba="0.8 0.8 0.8 1" /></material><geometry><mesh filename="../../all_meshes/parts/drawer.obj" scale="1 1.3133333333333332 1.3133333333333332" /></geometry></visual><collision><origin xyz="0 0 0" rpy="0 0 0" /><geometry><mesh filename="../../all_meshes/parts/drawer.obj" scale="1 1.3133333333333332 1.3133333333333332" /></geometry></collision><inertial><mass value="0.2" /><inertia ixx="1e-4" ixy="0" ixz="0" iyy="1e-4" iyz="0" izz="1e-4" /></inertial></link><joint name="drawer5_to_base_link" type="prismatic"><axis xyz="1 0 0" /><limit effort="5" lower="0" upper="0.4" velocity="2.283" /><origin xyz="0 0.6666666666666666 0.6666666666666666" rpy="0.0 0.0 0.0" /><parent link="base_link" /><child link="drawer5" /></joint><link name="handle6"><visual><origin xyz="0 0 0" rpy="0 0 0" /><material name="white"><color rgba="0.8 0.8 0.8 1" /></material><geometry><mesh filename="../../all_meshes/parts/handle.obj" scale="1 1 1" /></geometry></visual><collision><origin xyz="0 0 0" rpy="0 0 0" /><geometry><mesh filename="../../all_meshes/parts/handle.obj" scale="1 1 1" /></geometry></collision><inertial><mass value="0.2" /><inertia ixx="1e-4" ixy="0" ixz="0" iyy="1e-4" iyz="0" izz="1e-4" /></inertial></link><joint name="handle6_to_doorL0" type="fixed"><axis xyz="1 0 0" /><limit effort="5" lower="0" upper="1.57" velocity="2.283" /><origin xyz="0 0.2777777777777778 0.3333333333333333" rpy="0.0 0.0 0.0" /><parent link="doorL0" /><child link="handle6" /></joint><link name="handle7"><visual><origin xyz="0 0 0" rpy="0 0 0" /><material name="white"><color rgba="0.8 0.8 0.8 1" /></material><geometry><mesh filename="../../all_meshes/parts/handle.obj" scale="1 1 1" /></geometry></visual><collision><origin xyz="0 0 0" rpy="0 0 0" /><geometry><mesh filename="../../all_meshes/parts/handle.obj" scale="1 1 1" /></geometry></collision><inertial><mass value="0.2" /><inertia ixx="1e-4" ixy="0" ixz="0" iyy="1e-4" iyz="0" izz="1e-4" /></inertial></link><joint name="handle7_to_doorR1" type="fixed"><axis xyz="1 0 0" /><limit effort="5" lower="0" upper="1.57" velocity="2.283" /><origin xyz="0 -0.2777777777777778 0.3333333333333333" rpy="0.0 0.0 0.0" /><parent link="doorR1" /><child link="handle7" /></joint><link name="handle8"><visual><origin xyz="0 0 0" rpy="0 0 0" /><material name="white"><color rgba="0.8 0.8 0.8 1" /></material><geometry><mesh filename="../../all_meshes/parts/handle.obj" scale="1 1 1" /></geometry></visual><collision><origin xyz="0 0 0" rpy="0 0 0" /><geometry><mesh filename="../../all_meshes/parts/handle.obj" scale="1 1 1" /></geometry></collision><inertial><mass value="0.2" /><inertia ixx="1e-4" ixy="0" ixz="0" iyy="1e-4" iyz="0" izz="1e-4" /></inertial></link><joint name="handle8_to_doorR2" type="fixed"><axis xyz="1 0 0" /><limit effort="5" lower="0" upper="1.57" velocity="2.283" /><origin xyz="0 -0.2777777777777778 0.3333333333333333" rpy="0.0 0.0 0.0" /><parent link="doorR2" /><child link="handle8" /></joint><link name="handle9"><visual><origin xyz="0 0 0" rpy="0 0 0" /><material name="white"><color rgba="0.8 0.8 0.8 1" /></material><geometry><mesh filename="../../all_meshes/parts/handle.obj" scale="1 1 1" /></geometry></visual><collision><origin xyz="0 0 0" rpy="0 0 0" /><geometry><mesh filename="../../all_meshes/parts/handle.obj" scale="1 1 1" /></geometry></collision><inertial><mass value="0.2" /><inertia ixx="1e-4" ixy="0" ixz="0" iyy="1e-4" iyz="0" izz="1e-4" /></inertial></link><joint name="handle9_to_drawer3" type="fixed"><axis xyz="0 0 1" /><limit effort="5" lower="0" upper="1.57" velocity="2.283" /><origin xyz="0 0.16666666666666666 0.16666666666666666" rpy="1.5707963267948963 0.0 0.0" /><parent link="drawer3" /><child link="handle9" /></joint><link name="handle10"><visual><origin xyz="0 0 0" rpy="0 0 0" /><material name="white"><color rgba="0.8 0.8 0.8 1" /></material><geometry><mesh filename="../../all_meshes/parts/handle.obj" scale="1 1 1" /></geometry></visual><collision><origin xyz="0 0 0" rpy="0 0 0" /><geometry><mesh filename="../../all_meshes/parts/handle.obj" scale="1 1 1" /></geometry></collision><inertial><mass value="0.2" /><inertia ixx="1e-4" ixy="0" ixz="0" iyy="1e-4" iyz="0" izz="1e-4" /></inertial></link><joint name="handle10_to_drawer4" type="fixed"><axis xyz="0 0 1" /><limit effort="5" lower="0" upper="1.57" velocity="2.283" /><origin xyz="0 0.16666666666666666 0.16666666666666666" rpy="1.5707963267948963 0.0 0.0" /><parent link="drawer4" /><child link="handle10" /></joint><link name="handle11"><visual><origin xyz="0 0 0" rpy="0 0 0" /><material name="white"><color rgba="0.8 0.8 0.8 1" /></material><geometry><mesh filename="../../all_meshes/parts/handle.obj" scale="1 1 1" /></geometry></visual><collision><origin xyz="0 0 0" rpy="0 0 0" /><geometry><mesh filename="../../all_meshes/parts/handle.obj" scale="1 1 1" /></geometry></collision><inertial><mass value="0.2" /><inertia ixx="1e-4" ixy="0" ixz="0" iyy="1e-4" iyz="0" izz="1e-4" /></inertial></link><joint name="handle11_to_drawer5" type="fixed"><axis xyz="0 0 1" /><limit effort="5" lower="0" upper="1.57" velocity="2.283" /><origin xyz="0 0.16666666666666666 0.16666666666666666" rpy="1.5707963267948963 0.0 0.0" /><parent link="drawer5" /><child link="handle11" /></joint></robot>