<?xml version='1.0' encoding='utf-8'?>
<robot name="my_urdf"><link name="base_link"><visual><origin xyz="0 0 0" rpy="0.0 0.0 0.0" /><material name="white"><color rgba="0.8 0.8 0.8 1" /></material><geometry><mesh filename="../../all_meshes/cabinet.obj" scale="1 1 1" /></geometry></visual><collision><origin xyz="0 0 0" rpy="0.0 0.0 0.0" /><geometry><mesh filename="../../all_meshes/cabinet.obj" scale="1 1 1" /></geometry></collision><inertial><mass value="1" /><inertia ixx="1e-4" ixy="0" ixz="0" iyy="1e-4" iyz="0" izz="1e-4" /></inertial></link><link name="doorL0"><visual><origin xyz="0 0 0" rpy="0 0 0" /><material name="white"><color rgba="0.8 0.8 0.8 1" /></material><geometry><mesh filename="../../all_meshes/parts/doorL.obj" scale="1 1.99 2.6566666666666667" /></geometry></visual><collision><origin xyz="0 0 0" rpy="0 0 0" /><geometry><mesh filename="../../all_meshes/parts/doorL.obj" scale="1 1.99 2.6566666666666667" /></geometry></collision><inertial><mass value="0.2" /><inertia ixx="1e-4" ixy="0" ixz="0" iyy="1e-4" iyz="0" izz="1e-4" /></inertial></link><joint name="doorL0_to_base_link" type="revolute"><axis xyz="0 0 1" /><limit effort="5" lower="-1.57" upper="0" velocity="2.283" /><origin xyz="0 0.0 0.3333333333333333" rpy="0.0 0.0 0.0" /><parent link="base_link" /><child link="doorL0" /></joint><link name="doorR1"><visual><origin xyz="0 0 0" rpy="0 0 0" /><material name="white"><color rgba="0.8 0.8 0.8 1" /></material><geometry><mesh filename="../../all_meshes/parts/doorR.obj" scale="1 1.99 2.6566666666666667" /></geometry></visual><collision><origin xyz="0 0 0" rpy="0 0 0" /><geometry><mesh filename="../../all_meshes/parts/doorR.obj" scale="1 1.99 2.6566666666666667" /></geometry></collision><inertial><mass value="0.2" /><inertia ixx="1e-4" ixy="0" ixz="0" iyy="1e-4" iyz="0" izz="1e-4" /></inertial></link><joint name="doorR1_to_base_link" type="revolute"><axis xyz="0 0 1" /><limit effort="5" lower="0" upper="1.57" velocity="2.283" /><origin xyz="0 1.0 0.3333333333333333" rpy="-0.0 -0.0 -0.0" /><parent link="base_link" /><child link="doorR1" /></joint><link name="doorL2"><visual><origin xyz="0 0 0" rpy="0 0 0" /><material name="white"><color rgba="0.8 0.8 0.8 1" /></material><geometry><mesh filename="../../all_meshes/parts/doorL.obj" scale="1 1.99 1.3233333333333333" /></geometry></visual><collision><origin xyz="0 0 0" rpy="0 0 0" /><geometry><mesh filename="../../all_meshes/parts/doorL.obj" scale="1 1.99 1.3233333333333333" /></geometry></collision><inertial><mass value="0.2" /><inertia ixx="1e-4" ixy="0" ixz="0" iyy="1e-4" iyz="0" izz="1e-4" /></inertial></link><joint name="doorL2_to_base_link" type="revolute"><axis xyz="0 0 1" /><limit effort="5" lower="-1.57" upper="0" velocity="2.283" /><origin xyz="0 0.0 0.0" rpy="0.0 0.0 0.0" /><parent link="base_link" /><child link="doorL2" /></joint><link name="doorR3"><visual><origin xyz="0 0 0" rpy="0 0 0" /><material name="white"><color rgba="0.8 0.8 0.8 1" /></material><geometry><mesh filename="../../all_meshes/parts/doorR.obj" scale="1 1.99 1.3233333333333333" /></geometry></visual><collision><origin xyz="0 0 0" rpy="0 0 0" /><geometry><mesh filename="../../all_meshes/parts/doorR.obj" scale="1 1.99 1.3233333333333333" /></geometry></collision><inertial><mass value="0.2" /><inertia ixx="1e-4" ixy="0" ixz="0" iyy="1e-4" iyz="0" izz="1e-4" /></inertial></link><joint name="doorR3_to_base_link" type="revolute"><axis xyz="0 0 1" /><limit effort="5" lower="0" upper="1.57" velocity="2.283" /><origin xyz="0 1.0 0.0" rpy="-0.0 -0.0 -0.0" /><parent link="base_link" /><child link="doorR3" /></joint><link name="knob4"><visual><origin xyz="0 0 0" rpy="0 0 0" /><material name="white"><color rgba="0.8 0.8 0.8 1" /></material><geometry><mesh filename="../../all_meshes/parts/knob.obj" scale="1 1 1" /></geometry></visual><collision><origin xyz="0 0 0" rpy="0 0 0" /><geometry><mesh filename="../../all_meshes/parts/knob.obj" scale="1 1 1" /></geometry></collision><inertial><mass value="0.2" /><inertia ixx="1e-4" ixy="0" ixz="0" iyy="1e-4" iyz="0" izz="1e-4" /></inertial></link><joint name="knob4_to_doorL0" type="fixed"><axis xyz="1 0 0" /><limit effort="5" lower="0" upper="1.57" velocity="2.283" /><origin xyz="0 0.4166666666666667 0.3333333333333333" rpy="0.0 0.0 0.0" /><parent link="doorL0" /><child link="knob4" /></joint><link name="knob5"><visual><origin xyz="0 0 0" rpy="0 0 0" /><material name="white"><color rgba="0.8 0.8 0.8 1" /></material><geometry><mesh filename="../../all_meshes/parts/knob.obj" scale="1 1 1" /></geometry></visual><collision><origin xyz="0 0 0" rpy="0 0 0" /><geometry><mesh filename="../../all_meshes/parts/knob.obj" scale="1 1 1" /></geometry></collision><inertial><mass value="0.2" /><inertia ixx="1e-4" ixy="0" ixz="0" iyy="1e-4" iyz="0" izz="1e-4" /></inertial></link><joint name="knob5_to_doorR1" type="fixed"><axis xyz="1 0 0" /><limit effort="5" lower="0" upper="1.57" velocity="2.283" /><origin xyz="0 -0.4166666666666667 0.3333333333333333" rpy="0.0 0.0 0.0" /><parent link="doorR1" /><child link="knob5" /></joint><link name="knob6"><visual><origin xyz="0 0 0" rpy="0 0 0" /><material name="white"><color rgba="0.8 0.8 0.8 1" /></material><geometry><mesh filename="../../all_meshes/parts/knob.obj" scale="1 1 1" /></geometry></visual><collision><origin xyz="0 0 0" rpy="0 0 0" /><geometry><mesh filename="../../all_meshes/parts/knob.obj" scale="1 1 1" /></geometry></collision><inertial><mass value="0.2" /><inertia ixx="1e-4" ixy="0" ixz="0" iyy="1e-4" iyz="0" izz="1e-4" /></inertial></link><joint name="knob6_to_doorL2" type="fixed"><axis xyz="1 0 0" /><limit effort="5" lower="0" upper="1.57" velocity="2.283" /><origin xyz="0 0.4166666666666667 0.16666666666666666" rpy="0.0 0.0 0.0" /><parent link="doorL2" /><child link="knob6" /></joint><link name="knob7"><visual><origin xyz="0 0 0" rpy="0 0 0" /><material name="white"><color rgba="0.8 0.8 0.8 1" /></material><geometry><mesh filename="../../all_meshes/parts/knob.obj" scale="1 1 1" /></geometry></visual><collision><origin xyz="0 0 0" rpy="0 0 0" /><geometry><mesh filename="../../all_meshes/parts/knob.obj" scale="1 1 1" /></geometry></collision><inertial><mass value="0.2" /><inertia ixx="1e-4" ixy="0" ixz="0" iyy="1e-4" iyz="0" izz="1e-4" /></inertial></link><joint name="knob7_to_doorR3" type="fixed"><axis xyz="1 0 0" /><limit effort="5" lower="0" upper="1.57" velocity="2.283" /><origin xyz="0 -0.4166666666666667 0.16666666666666666" rpy="0.0 0.0 0.0" /><parent link="doorR3" /><child link="knob7" /></joint></robot>