<?xml version='1.0' encoding='utf-8'?>
<robot name="my_urdf"><link name="base_link"><visual><origin xyz="0 0 0" rpy="0.0 0.0 0.0" /><material name="white"><color rgba="0.8 0.8 0.8 1" /></material><geometry><mesh filename="../../all_meshes/cabinet.obj" scale="1 1 1" /></geometry></visual><collision><origin xyz="0 0 0" rpy="0.0 0.0 0.0" /><geometry><mesh filename="../../all_meshes/cabinet.obj" scale="1 1 1" /></geometry></collision><inertial><mass value="1" /><inertia ixx="1e-4" ixy="0" ixz="0" iyy="1e-4" iyz="0" izz="1e-4" /></inertial></link><link name="drawer0"><visual><origin xyz="0 0 0" rpy="0 0 0" /><material name="white"><color rgba="0.8 0.8 0.8 1" /></material><geometry><mesh filename="../../all_meshes/parts/drawer.obj" scale="1 1.3133333333333332 0.98" /></geometry></visual><collision><origin xyz="0 0 0" rpy="0 0 0" /><geometry><mesh filename="../../all_meshes/parts/drawer.obj" scale="1 1.3133333333333332 0.98" /></geometry></collision><inertial><mass value="0.2" /><inertia ixx="1e-4" ixy="0" ixz="0" iyy="1e-4" iyz="0" izz="1e-4" /></inertial></link><joint name="drawer0_to_base_link" type="prismatic"><axis xyz="1 0 0" /><limit effort="5" lower="0" upper="0.4" velocity="2.283" /><origin xyz="0 0.0 0.0" rpy="0.0 0.0 0.0" /><parent link="base_link" /><child link="drawer0" /></joint><link name="drawer1"><visual><origin xyz="0 0 0" rpy="0 0 0" /><material name="white"><color rgba="0.8 0.8 0.8 1" /></material><geometry><mesh filename="../../all_meshes/parts/drawer.obj" scale="1 0.98 0.98" /></geometry></visual><collision><origin xyz="0 0 0" rpy="0 0 0" /><geometry><mesh filename="../../all_meshes/parts/drawer.obj" scale="1 0.98 0.98" /></geometry></collision><inertial><mass value="0.2" /><inertia ixx="1e-4" ixy="0" ixz="0" iyy="1e-4" iyz="0" izz="1e-4" /></inertial></link><joint name="drawer1_to_base_link" type="prismatic"><axis xyz="1 0 0" /><limit effort="5" lower="0" upper="0.4" velocity="2.283" /><origin xyz="0 0.75 0.75" rpy="0.0 0.0 0.0" /><parent link="base_link" /><child link="drawer1" /></joint><link name="drawer2"><visual><origin xyz="0 0 0" rpy="0 0 0" /><material name="white"><color rgba="0.8 0.8 0.8 1" /></material><geometry><mesh filename="../../all_meshes/parts/drawer.obj" scale="1 0.98 0.98" /></geometry></visual><collision><origin xyz="0 0 0" rpy="0 0 0" /><geometry><mesh filename="../../all_meshes/parts/drawer.obj" scale="1 0.98 0.98" /></geometry></collision><inertial><mass value="0.2" /><inertia ixx="1e-4" ixy="0" ixz="0" iyy="1e-4" iyz="0" izz="1e-4" /></inertial></link><joint name="drawer2_to_base_link" type="prismatic"><axis xyz="1 0 0" /><limit effort="5" lower="0" upper="0.4" velocity="2.283" /><origin xyz="0 0.75 0.5" rpy="0.0 0.0 0.0" /><parent link="base_link" /><child link="drawer2" /></joint><link name="drawer3"><visual><origin xyz="0 0 0" rpy="0 0 0" /><material name="white"><color rgba="0.8 0.8 0.8 1" /></material><geometry><mesh filename="../../all_meshes/parts/drawer.obj" scale="1 0.98 0.98" /></geometry></visual><collision><origin xyz="0 0 0" rpy="0 0 0" /><geometry><mesh filename="../../all_meshes/parts/drawer.obj" scale="1 0.98 0.98" /></geometry></collision><inertial><mass value="0.2" /><inertia ixx="1e-4" ixy="0" ixz="0" iyy="1e-4" iyz="0" izz="1e-4" /></inertial></link><joint name="drawer3_to_base_link" type="prismatic"><axis xyz="1 0 0" /><limit effort="5" lower="0" upper="0.4" velocity="2.283" /><origin xyz="0 0.5 0.25" rpy="0.0 0.0 0.0" /><parent link="base_link" /><child link="drawer3" /></joint><link name="drawer4"><visual><origin xyz="0 0 0" rpy="0 0 0" /><material name="white"><color rgba="0.8 0.8 0.8 1" /></material><geometry><mesh filename="../../all_meshes/parts/drawer.obj" scale="1 0.98 0.98" /></geometry></visual><collision><origin xyz="0 0 0" rpy="0 0 0" /><geometry><mesh filename="../../all_meshes/parts/drawer.obj" scale="1 0.98 0.98" /></geometry></collision><inertial><mass value="0.2" /><inertia ixx="1e-4" ixy="0" ixz="0" iyy="1e-4" iyz="0" izz="1e-4" /></inertial></link><joint name="drawer4_to_base_link" type="prismatic"><axis xyz="1 0 0" /><limit effort="5" lower="0" upper="0.4" velocity="2.283" /><origin xyz="0 0.5 0.5" rpy="0.0 0.0 0.0" /><parent link="base_link" /><child link="drawer4" /></joint><link name="drawer5"><visual><origin xyz="0 0 0" rpy="0 0 0" /><material name="white"><color rgba="0.8 0.8 0.8 1" /></material><geometry><mesh filename="../../all_meshes/parts/drawer.obj" scale="1 0.98 0.98" /></geometry></visual><collision><origin xyz="0 0 0" rpy="0 0 0" /><geometry><mesh filename="../../all_meshes/parts/drawer.obj" scale="1 0.98 0.98" /></geometry></collision><inertial><mass value="0.2" /><inertia ixx="1e-4" ixy="0" ixz="0" iyy="1e-4" iyz="0" izz="1e-4" /></inertial></link><joint name="drawer5_to_base_link" type="prismatic"><axis xyz="1 0 0" /><limit effort="5" lower="0" upper="0.4" velocity="2.283" /><origin xyz="0 0.5 0.75" rpy="0.0 0.0 0.0" /><parent link="base_link" /><child link="drawer5" /></joint><link name="drawer6"><visual><origin xyz="0 0 0" rpy="0 0 0" /><material name="white"><color rgba="0.8 0.8 0.8 1" /></material><geometry><mesh filename="../../all_meshes/parts/drawer.obj" scale="1 0.98 0.98" /></geometry></visual><collision><origin xyz="0 0 0" rpy="0 0 0" /><geometry><mesh filename="../../all_meshes/parts/drawer.obj" scale="1 0.98 0.98" /></geometry></collision><inertial><mass value="0.2" /><inertia ixx="1e-4" ixy="0" ixz="0" iyy="1e-4" iyz="0" izz="1e-4" /></inertial></link><joint name="drawer6_to_base_link" type="prismatic"><axis xyz="1 0 0" /><limit effort="5" lower="0" upper="0.4" velocity="2.283" /><origin xyz="0 0.25 0.25" rpy="0.0 0.0 0.0" /><parent link="base_link" /><child link="drawer6" /></joint><link name="drawer7"><visual><origin xyz="0 0 0" rpy="0 0 0" /><material name="white"><color rgba="0.8 0.8 0.8 1" /></material><geometry><mesh filename="../../all_meshes/parts/drawer.obj" scale="1 0.98 0.98" /></geometry></visual><collision><origin xyz="0 0 0" rpy="0 0 0" /><geometry><mesh filename="../../all_meshes/parts/drawer.obj" scale="1 0.98 0.98" /></geometry></collision><inertial><mass value="0.2" /><inertia ixx="1e-4" ixy="0" ixz="0" iyy="1e-4" iyz="0" izz="1e-4" /></inertial></link><joint name="drawer7_to_base_link" type="prismatic"><axis xyz="1 0 0" /><limit effort="5" lower="0" upper="0.4" velocity="2.283" /><origin xyz="0 0.75 0.25" rpy="0.0 0.0 0.0" /><parent link="base_link" /><child link="drawer7" /></joint><link name="drawer8"><visual><origin xyz="0 0 0" rpy="0 0 0" /><material name="white"><color rgba="0.8 0.8 0.8 1" /></material><geometry><mesh filename="../../all_meshes/parts/drawer.obj" scale="1 0.98 0.98" /></geometry></visual><collision><origin xyz="0 0 0" rpy="0 0 0" /><geometry><mesh filename="../../all_meshes/parts/drawer.obj" scale="1 0.98 0.98" /></geometry></collision><inertial><mass value="0.2" /><inertia ixx="1e-4" ixy="0" ixz="0" iyy="1e-4" iyz="0" izz="1e-4" /></inertial></link><joint name="drawer8_to_base_link" type="prismatic"><axis xyz="1 0 0" /><limit effort="5" lower="0" upper="0.4" velocity="2.283" /><origin xyz="0 0.25 0.75" rpy="0.0 0.0 0.0" /><parent link="base_link" /><child link="drawer8" /></joint><link name="drawer9"><visual><origin xyz="0 0 0" rpy="0 0 0" /><material name="white"><color rgba="0.8 0.8 0.8 1" /></material><geometry><mesh filename="../../all_meshes/parts/drawer.obj" scale="1 0.98 0.98" /></geometry></visual><collision><origin xyz="0 0 0" rpy="0 0 0" /><geometry><mesh filename="../../all_meshes/parts/drawer.obj" scale="1 0.98 0.98" /></geometry></collision><inertial><mass value="0.2" /><inertia ixx="1e-4" ixy="0" ixz="0" iyy="1e-4" iyz="0" izz="1e-4" /></inertial></link><joint name="drawer9_to_base_link" type="prismatic"><axis xyz="1 0 0" /><limit effort="5" lower="0" upper="0.4" velocity="2.283" /><origin xyz="0 0.0 0.25" rpy="0.0 0.0 0.0" /><parent link="base_link" /><child link="drawer9" /></joint><link name="drawer10"><visual><origin xyz="0 0 0" rpy="0 0 0" /><material name="white"><color rgba="0.8 0.8 0.8 1" /></material><geometry><mesh filename="../../all_meshes/parts/drawer.obj" scale="1 0.98 0.98" /></geometry></visual><collision><origin xyz="0 0 0" rpy="0 0 0" /><geometry><mesh filename="../../all_meshes/parts/drawer.obj" scale="1 0.98 0.98" /></geometry></collision><inertial><mass value="0.2" /><inertia ixx="1e-4" ixy="0" ixz="0" iyy="1e-4" iyz="0" izz="1e-4" /></inertial></link><joint name="drawer10_to_base_link" type="prismatic"><axis xyz="1 0 0" /><limit effort="5" lower="0" upper="0.4" velocity="2.283" /><origin xyz="0 0.0 0.5" rpy="0.0 0.0 0.0" /><parent link="base_link" /><child link="drawer10" /></joint><link name="drawer11"><visual><origin xyz="0 0 0" rpy="0 0 0" /><material name="white"><color rgba="0.8 0.8 0.8 1" /></material><geometry><mesh filename="../../all_meshes/parts/drawer.obj" scale="1 0.98 0.98" /></geometry></visual><collision><origin xyz="0 0 0" rpy="0 0 0" /><geometry><mesh filename="../../all_meshes/parts/drawer.obj" scale="1 0.98 0.98" /></geometry></collision><inertial><mass value="0.2" /><inertia ixx="1e-4" ixy="0" ixz="0" iyy="1e-4" iyz="0" izz="1e-4" /></inertial></link><joint name="drawer11_to_base_link" type="prismatic"><axis xyz="1 0 0" /><limit effort="5" lower="0" upper="0.4" velocity="2.283" /><origin xyz="0 0.0 0.75" rpy="0.0 0.0 0.0" /><parent link="base_link" /><child link="drawer11" /></joint><link name="drawer12"><visual><origin xyz="0 0 0" rpy="0 0 0" /><material name="white"><color rgba="0.8 0.8 0.8 1" /></material><geometry><mesh filename="../../all_meshes/parts/drawer.obj" scale="1 1.3133333333333332 0.98" /></geometry></visual><collision><origin xyz="0 0 0" rpy="0 0 0" /><geometry><mesh filename="../../all_meshes/parts/drawer.obj" scale="1 1.3133333333333332 0.98" /></geometry></collision><inertial><mass value="0.2" /><inertia ixx="1e-4" ixy="0" ixz="0" iyy="1e-4" iyz="0" izz="1e-4" /></inertial></link><joint name="drawer12_to_base_link" type="prismatic"><axis xyz="1 0 0" /><limit effort="5" lower="0" upper="0.4" velocity="2.283" /><origin xyz="0 0.6666666666666666 0.0" rpy="0.0 0.0 0.0" /><parent link="base_link" /><child link="drawer12" /></joint><link name="drawer13"><visual><origin xyz="0 0 0" rpy="0 0 0" /><material name="white"><color rgba="0.8 0.8 0.8 1" /></material><geometry><mesh filename="../../all_meshes/parts/drawer.obj" scale="1 1.3133333333333332 0.98" /></geometry></visual><collision><origin xyz="0 0 0" rpy="0 0 0" /><geometry><mesh filename="../../all_meshes/parts/drawer.obj" scale="1 1.3133333333333332 0.98" /></geometry></collision><inertial><mass value="0.2" /><inertia ixx="1e-4" ixy="0" ixz="0" iyy="1e-4" iyz="0" izz="1e-4" /></inertial></link><joint name="drawer13_to_base_link" type="prismatic"><axis xyz="1 0 0" /><limit effort="5" lower="0" upper="0.4" velocity="2.283" /><origin xyz="0 0.3333333333333333 0.0" rpy="0.0 0.0 0.0" /><parent link="base_link" /><child link="drawer13" /></joint><link name="drawer14"><visual><origin xyz="0 0 0" rpy="0 0 0" /><material name="white"><color rgba="0.8 0.8 0.8 1" /></material><geometry><mesh filename="../../all_meshes/parts/drawer.obj" scale="1 0.98 0.98" /></geometry></visual><collision><origin xyz="0 0 0" rpy="0 0 0" /><geometry><mesh filename="../../all_meshes/parts/drawer.obj" scale="1 0.98 0.98" /></geometry></collision><inertial><mass value="0.2" /><inertia ixx="1e-4" ixy="0" ixz="0" iyy="1e-4" iyz="0" izz="1e-4" /></inertial></link><joint name="drawer14_to_base_link" type="prismatic"><axis xyz="1 0 0" /><limit effort="5" lower="0" upper="0.4" velocity="2.283" /><origin xyz="0 0.25 0.5" rpy="0.0 0.0 0.0" /><parent link="base_link" /><child link="drawer14" /></joint><link name="knob15"><visual><origin xyz="0 0 0" rpy="0 0 0" /><material name="white"><color rgba="0.8 0.8 0.8 1" /></material><geometry><mesh filename="../../all_meshes/parts/knob.obj" scale="1 1 1" /></geometry></visual><collision><origin xyz="0 0 0" rpy="0 0 0" /><geometry><mesh filename="../../all_meshes/parts/knob.obj" scale="1 1 1" /></geometry></collision><inertial><mass value="0.2" /><inertia ixx="1e-4" ixy="0" ixz="0" iyy="1e-4" iyz="0" izz="1e-4" /></inertial></link><joint name="knob15_to_drawer0" type="fixed"><axis xyz="0 0 1" /><limit effort="5" lower="0" upper="1.57" velocity="2.283" /><origin xyz="0 0.16666666666666666 0.125" rpy="1.5707963267948963 0.0 0.0" /><parent link="drawer0" /><child link="knob15" /></joint><link name="knob16"><visual><origin xyz="0 0 0" rpy="0 0 0" /><material name="white"><color rgba="0.8 0.8 0.8 1" /></material><geometry><mesh filename="../../all_meshes/parts/knob.obj" scale="1 1 1" /></geometry></visual><collision><origin xyz="0 0 0" rpy="0 0 0" /><geometry><mesh filename="../../all_meshes/parts/knob.obj" scale="1 1 1" /></geometry></collision><inertial><mass value="0.2" /><inertia ixx="1e-4" ixy="0" ixz="0" iyy="1e-4" iyz="0" izz="1e-4" /></inertial></link><joint name="knob16_to_drawer13" type="fixed"><axis xyz="0 0 1" /><limit effort="5" lower="0" upper="1.57" velocity="2.283" /><origin xyz="0 0.16666666666666666 0.125" rpy="1.5707963267948963 0.0 0.0" /><parent link="drawer13" /><child link="knob16" /></joint><link name="knob17"><visual><origin xyz="0 0 0" rpy="0 0 0" /><material name="white"><color rgba="0.8 0.8 0.8 1" /></material><geometry><mesh filename="../../all_meshes/parts/knob.obj" scale="1 1 1" /></geometry></visual><collision><origin xyz="0 0 0" rpy="0 0 0" /><geometry><mesh filename="../../all_meshes/parts/knob.obj" scale="1 1 1" /></geometry></collision><inertial><mass value="0.2" /><inertia ixx="1e-4" ixy="0" ixz="0" iyy="1e-4" iyz="0" izz="1e-4" /></inertial></link><joint name="knob17_to_drawer12" type="fixed"><axis xyz="0 0 1" /><limit effort="5" lower="0" upper="1.57" velocity="2.283" /><origin xyz="0 0.16666666666666666 0.125" rpy="1.5707963267948963 0.0 0.0" /><parent link="drawer12" /><child link="knob17" /></joint><link name="knob18"><visual><origin xyz="0 0 0" rpy="0 0 0" /><material name="white"><color rgba="0.8 0.8 0.8 1" /></material><geometry><mesh filename="../../all_meshes/parts/knob.obj" scale="1 1 1" /></geometry></visual><collision><origin xyz="0 0 0" rpy="0 0 0" /><geometry><mesh filename="../../all_meshes/parts/knob.obj" scale="1 1 1" /></geometry></collision><inertial><mass value="0.2" /><inertia ixx="1e-4" ixy="0" ixz="0" iyy="1e-4" iyz="0" izz="1e-4" /></inertial></link><joint name="knob18_to_drawer11" type="fixed"><axis xyz="0 0 1" /><limit effort="5" lower="0" upper="1.57" velocity="2.283" /><origin xyz="0 0.125 0.125" rpy="1.5707963267948963 0.0 0.0" /><parent link="drawer11" /><child link="knob18" /></joint><link name="knob19"><visual><origin xyz="0 0 0" rpy="0 0 0" /><material name="white"><color rgba="0.8 0.8 0.8 1" /></material><geometry><mesh filename="../../all_meshes/parts/knob.obj" scale="1 1 1" /></geometry></visual><collision><origin xyz="0 0 0" rpy="0 0 0" /><geometry><mesh filename="../../all_meshes/parts/knob.obj" scale="1 1 1" /></geometry></collision><inertial><mass value="0.2" /><inertia ixx="1e-4" ixy="0" ixz="0" iyy="1e-4" iyz="0" izz="1e-4" /></inertial></link><joint name="knob19_to_drawer10" type="fixed"><axis xyz="0 0 1" /><limit effort="5" lower="0" upper="1.57" velocity="2.283" /><origin xyz="0 0.125 0.125" rpy="1.5707963267948963 0.0 0.0" /><parent link="drawer10" /><child link="knob19" /></joint><link name="knob20"><visual><origin xyz="0 0 0" rpy="0 0 0" /><material name="white"><color rgba="0.8 0.8 0.8 1" /></material><geometry><mesh filename="../../all_meshes/parts/knob.obj" scale="1 1 1" /></geometry></visual><collision><origin xyz="0 0 0" rpy="0 0 0" /><geometry><mesh filename="../../all_meshes/parts/knob.obj" scale="1 1 1" /></geometry></collision><inertial><mass value="0.2" /><inertia ixx="1e-4" ixy="0" ixz="0" iyy="1e-4" iyz="0" izz="1e-4" /></inertial></link><joint name="knob20_to_drawer9" type="fixed"><axis xyz="0 0 1" /><limit effort="5" lower="0" upper="1.57" velocity="2.283" /><origin xyz="0 0.125 0.125" rpy="1.5707963267948963 0.0 0.0" /><parent link="drawer9" /><child link="knob20" /></joint><link name="knob21"><visual><origin xyz="0 0 0" rpy="0 0 0" /><material name="white"><color rgba="0.8 0.8 0.8 1" /></material><geometry><mesh filename="../../all_meshes/parts/knob.obj" scale="1 1 1" /></geometry></visual><collision><origin xyz="0 0 0" rpy="0 0 0" /><geometry><mesh filename="../../all_meshes/parts/knob.obj" scale="1 1 1" /></geometry></collision><inertial><mass value="0.2" /><inertia ixx="1e-4" ixy="0" ixz="0" iyy="1e-4" iyz="0" izz="1e-4" /></inertial></link><joint name="knob21_to_drawer8" type="fixed"><axis xyz="0 0 1" /><limit effort="5" lower="0" upper="1.57" velocity="2.283" /><origin xyz="0 0.125 0.125" rpy="1.5707963267948963 0.0 0.0" /><parent link="drawer8" /><child link="knob21" /></joint><link name="knob22"><visual><origin xyz="0 0 0" rpy="0 0 0" /><material name="white"><color rgba="0.8 0.8 0.8 1" /></material><geometry><mesh filename="../../all_meshes/parts/knob.obj" scale="1 1 1" /></geometry></visual><collision><origin xyz="0 0 0" rpy="0 0 0" /><geometry><mesh filename="../../all_meshes/parts/knob.obj" scale="1 1 1" /></geometry></collision><inertial><mass value="0.2" /><inertia ixx="1e-4" ixy="0" ixz="0" iyy="1e-4" iyz="0" izz="1e-4" /></inertial></link><joint name="knob22_to_drawer14" type="fixed"><axis xyz="0 0 1" /><limit effort="5" lower="0" upper="1.57" velocity="2.283" /><origin xyz="0 0.125 0.125" rpy="1.5707963267948963 0.0 0.0" /><parent link="drawer14" /><child link="knob22" /></joint><link name="knob23"><visual><origin xyz="0 0 0" rpy="0 0 0" /><material name="white"><color rgba="0.8 0.8 0.8 1" /></material><geometry><mesh filename="../../all_meshes/parts/knob.obj" scale="1 1 1" /></geometry></visual><collision><origin xyz="0 0 0" rpy="0 0 0" /><geometry><mesh filename="../../all_meshes/parts/knob.obj" scale="1 1 1" /></geometry></collision><inertial><mass value="0.2" /><inertia ixx="1e-4" ixy="0" ixz="0" iyy="1e-4" iyz="0" izz="1e-4" /></inertial></link><joint name="knob23_to_drawer6" type="fixed"><axis xyz="0 0 1" /><limit effort="5" lower="0" upper="1.57" velocity="2.283" /><origin xyz="0 0.125 0.125" rpy="1.5707963267948963 0.0 0.0" /><parent link="drawer6" /><child link="knob23" /></joint><link name="knob24"><visual><origin xyz="0 0 0" rpy="0 0 0" /><material name="white"><color rgba="0.8 0.8 0.8 1" /></material><geometry><mesh filename="../../all_meshes/parts/knob.obj" scale="1 1 1" /></geometry></visual><collision><origin xyz="0 0 0" rpy="0 0 0" /><geometry><mesh filename="../../all_meshes/parts/knob.obj" scale="1 1 1" /></geometry></collision><inertial><mass value="0.2" /><inertia ixx="1e-4" ixy="0" ixz="0" iyy="1e-4" iyz="0" izz="1e-4" /></inertial></link><joint name="knob24_to_drawer5" type="fixed"><axis xyz="0 0 1" /><limit effort="5" lower="0" upper="1.57" velocity="2.283" /><origin xyz="0 0.125 0.125" rpy="1.5707963267948963 0.0 0.0" /><parent link="drawer5" /><child link="knob24" /></joint><link name="knob25"><visual><origin xyz="0 0 0" rpy="0 0 0" /><material name="white"><color rgba="0.8 0.8 0.8 1" /></material><geometry><mesh filename="../../all_meshes/parts/knob.obj" scale="1 1 1" /></geometry></visual><collision><origin xyz="0 0 0" rpy="0 0 0" /><geometry><mesh filename="../../all_meshes/parts/knob.obj" scale="1 1 1" /></geometry></collision><inertial><mass value="0.2" /><inertia ixx="1e-4" ixy="0" ixz="0" iyy="1e-4" iyz="0" izz="1e-4" /></inertial></link><joint name="knob25_to_drawer4" type="fixed"><axis xyz="0 0 1" /><limit effort="5" lower="0" upper="1.57" velocity="2.283" /><origin xyz="0 0.125 0.125" rpy="1.5707963267948963 0.0 0.0" /><parent link="drawer4" /><child link="knob25" /></joint><link name="knob26"><visual><origin xyz="0 0 0" rpy="0 0 0" /><material name="white"><color rgba="0.8 0.8 0.8 1" /></material><geometry><mesh filename="../../all_meshes/parts/knob.obj" scale="1 1 1" /></geometry></visual><collision><origin xyz="0 0 0" rpy="0 0 0" /><geometry><mesh filename="../../all_meshes/parts/knob.obj" scale="1 1 1" /></geometry></collision><inertial><mass value="0.2" /><inertia ixx="1e-4" ixy="0" ixz="0" iyy="1e-4" iyz="0" izz="1e-4" /></inertial></link><joint name="knob26_to_drawer3" type="fixed"><axis xyz="0 0 1" /><limit effort="5" lower="0" upper="1.57" velocity="2.283" /><origin xyz="0 0.125 0.125" rpy="1.5707963267948963 0.0 0.0" /><parent link="drawer3" /><child link="knob26" /></joint><link name="knob27"><visual><origin xyz="0 0 0" rpy="0 0 0" /><material name="white"><color rgba="0.8 0.8 0.8 1" /></material><geometry><mesh filename="../../all_meshes/parts/knob.obj" scale="1 1 1" /></geometry></visual><collision><origin xyz="0 0 0" rpy="0 0 0" /><geometry><mesh filename="../../all_meshes/parts/knob.obj" scale="1 1 1" /></geometry></collision><inertial><mass value="0.2" /><inertia ixx="1e-4" ixy="0" ixz="0" iyy="1e-4" iyz="0" izz="1e-4" /></inertial></link><joint name="knob27_to_drawer2" type="fixed"><axis xyz="0 0 1" /><limit effort="5" lower="0" upper="1.57" velocity="2.283" /><origin xyz="0 0.125 0.125" rpy="1.5707963267948963 0.0 0.0" /><parent link="drawer2" /><child link="knob27" /></joint><link name="knob28"><visual><origin xyz="0 0 0" rpy="0 0 0" /><material name="white"><color rgba="0.8 0.8 0.8 1" /></material><geometry><mesh filename="../../all_meshes/parts/knob.obj" scale="1 1 1" /></geometry></visual><collision><origin xyz="0 0 0" rpy="0 0 0" /><geometry><mesh filename="../../all_meshes/parts/knob.obj" scale="1 1 1" /></geometry></collision><inertial><mass value="0.2" /><inertia ixx="1e-4" ixy="0" ixz="0" iyy="1e-4" iyz="0" izz="1e-4" /></inertial></link><joint name="knob28_to_drawer1" type="fixed"><axis xyz="0 0 1" /><limit effort="5" lower="0" upper="1.57" velocity="2.283" /><origin xyz="0 0.125 0.125" rpy="1.5707963267948963 0.0 0.0" /><parent link="drawer1" /><child link="knob28" /></joint><link name="knob29"><visual><origin xyz="0 0 0" rpy="0 0 0" /><material name="white"><color rgba="0.8 0.8 0.8 1" /></material><geometry><mesh filename="../../all_meshes/parts/knob.obj" scale="1 1 1" /></geometry></visual><collision><origin xyz="0 0 0" rpy="0 0 0" /><geometry><mesh filename="../../all_meshes/parts/knob.obj" scale="1 1 1" /></geometry></collision><inertial><mass value="0.2" /><inertia ixx="1e-4" ixy="0" ixz="0" iyy="1e-4" iyz="0" izz="1e-4" /></inertial></link><joint name="knob29_to_drawer7" type="fixed"><axis xyz="0 0 1" /><limit effort="5" lower="0" upper="1.57" velocity="2.283" /><origin xyz="0 0.125 0.125" rpy="1.5707963267948963 0.0 0.0" /><parent link="drawer7" /><child link="knob29" /></joint></robot>